<?xml version="1.0" ?>
<robot name="spot">
  <link name="body">
    <visual>
      <geometry>
        <mesh filename="package://spot/meshes/base/visual/body.obj"/>
      </geometry>
    </visual>
    <collision>
      <geometry>
        <mesh filename="package://spot/meshes/base/collision/body_collision.obj"/>
      </geometry>
    </collision>
  </link>
  <link name="base_link">
    <inertial>
      <origin xyz="0 0 -0.00496172"/>
      <mass value="16.70765207"/>
      <inertia ixx="0.081543792" ixy="0.0" ixz="0.0" iyy="0.549231154" iyz="0.0" izz="0.569454373"/>
    </inertial>
  </link>
  <joint name="base_link_joint" type="fixed">
    <origin rpy="0 0 0" xyz="0 0 0"/>
    <parent link="body"/>
    <child link="base_link"/>
  </joint>

  <!-- Front Left Hip Link -->
  <link name="fl_hip">
    <visual>
      <geometry>
        <mesh filename="package://spot/meshes/base/visual/front_left_hip.obj"/>
      </geometry>
    </visual>
    <inertial>
      <origin xyz="-0.01586739 0.00855842 0.00000903"/>
      <inertia ixx="0.00122166" ixy="-0.00017754" ixz="0.00000043" iyy="0.00158957" iyz="-0.00000049" izz="0.00172903"/>
      <mass value="1.13688339"/>
    </inertial>
  </link>

  <joint name="fl_hx" type="revolute">
    <origin rpy="0 0 0" xyz="0.29785 0.05500 0.00000"/>
    <axis xyz="1 0 0"/>
    <parent link="body"/>
    <child link="fl_hip"/>
    <!-- The velocity limits are for kinematic planning. The motors might move faster. -->
    <limit effort="45" lower="-0.785398" upper="0.785398" velocity="17"/>
  </joint>

  <transmission name="fl_hx_tran">
    <type>transmission_interface/SimpleTransmission</type>
    <joint name="fl_hx">
      <hardwareInterface>EffortJointInterface</hardwareInterface>
    </joint>
    <actuator name="fl_hx_motor">
      <hardwareInterface>EffortJointInterface</hardwareInterface>
    </actuator>
  </transmission>

  <!-- Front Left Upper Leg -->
  <link name="fl_uleg">
    <visual>
      <geometry>
        <mesh filename="package://spot/meshes/base/visual/front_left_upper_leg.obj"/>
      </geometry>
    </visual>
    <collision>
      <geometry>
        <mesh filename="package://spot/meshes/base/collision/left_upper_leg_collision.obj"/>
      </geometry>
    </collision>
    <inertial>
      <origin xyz="0.00214442 -0.01110184 -0.07881204"/>
      <inertia ixx="0.02692501" ixy="-0.00008782" ixz="0.00054873" iyy="0.02583907" iyz="0.00207146" izz="0.00318737"/>
      <mass value="2.25620359"/>
    </inertial>
  </link>

  <drake:collision_filter_group name="group_fl_uleg">
    <drake:member link="body"/>
    <drake:member link="fl_uleg"/>
    <drake:ignored_collision_filter_group name="group_fl_uleg"/>
  </drake:collision_filter_group>

  <joint name="fl_hy" type="revolute">
    <origin rpy="0 0 0" xyz="0.0 0.110945 0.0"/>
    <axis xyz="0 1 0"/>
    <parent link="fl_hip"/>
    <child link="fl_uleg"/>
    <!-- The velocity limits are for kinematic planning. The motors might move faster. -->
    <limit effort="45" lower="-0.898845" upper="2.295108" velocity="17"/>
  </joint>

  <transmission name="fl_hy_tran">
    <type>transmission_interface/SimpleTransmission</type>
    <joint name="fl_hy">
      <hardwareInterface>EffortJointInterface</hardwareInterface>
    </joint>
    <actuator name="fl_hy_motor">
      <hardwareInterface>EffortJointInterface</hardwareInterface>
    </actuator>
  </transmission>

  <!-- Front Left Lower Leg -->
  <link name="fl_lleg">
    <visual>
      <geometry>
        <mesh filename="package://spot/meshes/base/visual/front_left_lower_leg.obj"/>
      </geometry>
   </visual>
    <collision>
      <geometry>
        <mesh filename="package://spot/meshes/base/collision/left_lower_leg_collision.obj"/>
      </geometry>
    </collision>
    <collision>
      <origin xyz="0.0 0.0 -0.3365" rpy="0 0 0" />
      <geometry>
        <sphere radius="0.036"/>
      </geometry>
      <drake:proximity_properties>
        <drake:mu_static value="0.8"/>
        <drake:mu_dynamic value="0.7"/>
        <drake:hunt_crossley_dissipation value="2"/>
      </drake:proximity_properties>
    </collision>
    <inertial>
      <origin xyz="0.00597360 0.0 -0.17466427"/>
      <inertia ixx="0.00701356" ixy="0.0" ixz="0.00006600" iyy="0.00709946" iyz="0.0" izz="0.00014529"/>
      <mass value="0.330"/>
    </inertial>
  </link>
  <frame link="fl_lleg" name="front_left_foot_center" xyz="0.0 0.0 -0.3365"/>

  <joint name="fl_kn" type="revolute">
    <origin rpy="0 0 0" xyz="0.025 0.000 -0.3205"/>
    <axis xyz="0 1 0"/>
    <parent link="fl_uleg"/>
    <child link="fl_lleg"/>
    <!-- The velocity limits are for kinematic planning and apply to the linkage
    input, which is modelled as a variable transmission outside of this URDF.
    Due to the high gear ratio, the limits at the motor seem very high.-->
    <limit effort="115" lower="-2.7929" upper="-0.2471" velocity="900"/>
  </joint>

  <transmission name="fl_kn_tran">
    <type>transmission_interface/SimpleTransmission</type>
    <joint name="fl_kn">
      <hardwareInterface>EffortJointInterface</hardwareInterface>
    </joint>
    <actuator name="fl_kn_motor">
      <hardwareInterface>EffortJointInterface</hardwareInterface>
    </actuator>
  </transmission>

  <!-- Front Right Hip -->
  <link name="fr_hip">
    <visual>
      <geometry>
        <mesh filename="package://spot/meshes/base/visual/front_right_hip.obj"/>
      </geometry>
   </visual>
    <inertial>
      <origin xyz="-0.01586739 -0.00855842 0.00000903"/>
      <inertia ixx="0.00122166" ixy="0.00017754" ixz="0.00000043" iyy="0.00158957" iyz="0.00000049" izz="0.00172903"/>
      <mass value="1.13688339"/>
    </inertial>
  </link>

  <joint name="fr_hx" type="revolute">
    <origin rpy="0 0 0" xyz="0.29785 -0.05500 0.00000"/>
    <axis xyz="1 0 0"/>
    <parent link="body"/>
    <child link="fr_hip"/>
    <!-- The velocity limits are for kinematic planning. The motors might move faster. -->
    <limit effort="45" lower="-0.785398" upper="0.785398" velocity="17"/>
  </joint>

  <transmission name="fr_hx_tran">
    <type>transmission_interface/SimpleTransmission</type>
    <joint name="fr_hx">
      <hardwareInterface>EffortJointInterface</hardwareInterface>
    </joint>
    <actuator name="fr_hx_motor">
      <hardwareInterface>EffortJointInterface</hardwareInterface>
    </actuator>
  </transmission>

  <!-- Front Right Upper Leg -->
  <link name="fr_uleg">
    <visual>
      <geometry>
        <mesh filename="package://spot/meshes/base/visual/front_right_upper_leg.obj"/>
      </geometry>
   </visual>
    <collision>
      <geometry>
        <mesh filename="package://spot/meshes/base/collision/right_upper_leg_collision.obj"/>
      </geometry>
    </collision>
    <inertial>
      <origin xyz="0.00214442 0.01110184 -0.07881204"/>
      <inertia ixx="0.02692501" ixy="0.00008782" ixz="0.00054873" iyy="0.02583907" iyz="-0.00207146" izz="0.00318737"/>
      <mass value="2.25620359"/>
    </inertial>
  </link>

  <drake:collision_filter_group name="group_fr_uleg">
    <drake:member link="body"/>
    <drake:member link="fr_uleg"/>
    <drake:ignored_collision_filter_group name="group_fr_uleg"/>
  </drake:collision_filter_group>

  <joint name="fr_hy" type="revolute">
    <origin rpy="0 0 0" xyz="0.0 -0.110945 0.0"/>
    <axis xyz="0 1 0"/>
    <parent link="fr_hip"/>
    <child link="fr_uleg"/>
    <!-- The velocity limits are for kinematic planning. The motors might move faster. -->
    <limit effort="45" lower="-0.898845" upper="2.295108" velocity="17"/>
  </joint>

  <transmission name="fr_hy_tran">
    <type>transmission_interface/SimpleTransmission</type>
    <joint name="fr_hy">
      <hardwareInterface>EffortJointInterface</hardwareInterface>
    </joint>
    <actuator name="fr_hy_motor">
      <hardwareInterface>EffortJointInterface</hardwareInterface>
    </actuator>
  </transmission>

  <!-- Front Right Lower Leg -->
  <link name="fr_lleg">
    <visual>
      <geometry>
        <mesh filename="package://spot/meshes/base/visual/front_right_lower_leg.obj"/>
      </geometry>
   </visual>
   <collision>
      <geometry>
        <mesh filename="package://spot/meshes/base/collision/right_lower_leg_collision.obj"/>
      </geometry>
    </collision>
    <collision>
      <origin xyz="0.0 0.0 -0.3365" rpy="0 0 0" />
      <geometry>
        <sphere radius="0.036"/>
      </geometry>
      <drake:proximity_properties>
        <drake:mu_static value="0.8"/>
        <drake:mu_dynamic value="0.7"/>
        <drake:hunt_crossley_dissipation value="2"/>
      </drake:proximity_properties>
    </collision>
    <inertial>
      <origin xyz="0.00597360 0.0 -0.17466427"/>
      <inertia ixx="0.00701356" ixy="0.0" ixz="0.00006600" iyy="0.00709946" iyz="0.0" izz="0.00014529"/>
      <mass value="0.330"/>
    </inertial>
  </link>
  <frame link="fr_lleg" name="front_right_foot_center" xyz="0.0 0.0 -0.3365"/>

  <joint name="fr_kn" type="revolute">
    <origin rpy="0 0 0" xyz="0.025 0.000 -0.3205"/>
    <axis xyz="0 1 0"/>
    <parent link="fr_uleg"/>
    <child link="fr_lleg"/>
    <!-- The velocity limits are for kinematic planning and apply to the linkage
    input, which is modelled as a variable transmission outside of this URDF.
    Due to the high gear ratio, the limits at the motor seem very high.-->
    <limit effort="115" lower="-2.7929" upper="-0.2471" velocity="900"/>
  </joint>

  <transmission name="fr_kn_tran">
    <type>transmission_interface/SimpleTransmission</type>
    <joint name="fr_kn">
      <hardwareInterface>EffortJointInterface</hardwareInterface>
    </joint>
    <actuator name="fr_kn_motor">
      <hardwareInterface>EffortJointInterface</hardwareInterface>
    </actuator>
  </transmission>

  <!-- Rear Left Hip -->
  <link name="hl_hip">
    <visual>
      <geometry>
        <mesh filename="package://spot/meshes/base/visual/rear_left_hip.obj"/>
      </geometry>
   </visual>
    <inertial>
      <origin xyz="0.01586739 0.00855842 0.00000903"/>
      <inertia ixx="0.00122166" ixy="0.00017754" ixz="-0.00000043" iyy="0.00158957" iyz="-0.00000049" izz="0.00172903"/>
      <mass value="1.13688339"/>
    </inertial>
  </link>

  <joint name="hl_hx" type="revolute">
    <origin rpy="0 0 0" xyz="-0.29785 0.05500 0.00000"/>
    <axis xyz="1 0 0"/>
    <parent link="body"/>
    <child link="hl_hip"/>
    <!-- The velocity limits are for kinematic planning. The motors might move faster. -->
    <limit effort="45" lower="-0.785398" upper="0.785398" velocity="17"/>
  </joint>

  <transmission name="hl_hx_tran">
    <type>transmission_interface/SimpleTransmission</type>
    <joint name="hl_hx">
      <hardwareInterface>EffortJointInterface</hardwareInterface>
    </joint>
    <actuator name="hl_hx_motor">
      <hardwareInterface>EffortJointInterface</hardwareInterface>
    </actuator>
  </transmission>

  <!-- Rear Left Upper Leg -->
  <link name="hl_uleg">
    <visual>
      <geometry>
        <mesh filename="package://spot/meshes/base/visual/rear_left_upper_leg.obj"/>
      </geometry>
   </visual>
    <collision>
      <geometry>
        <mesh filename="package://spot/meshes/base/collision/left_upper_leg_collision.obj"/>
      </geometry>
    </collision>
    <inertial>
      <origin xyz="0.00214442 -0.01110184 -0.07881204"/>
      <inertia ixx="0.02692501" ixy="-0.00008782" ixz="0.00054873" iyy="0.02583907" iyz="0.00207146" izz="0.00318737"/>
      <mass value="2.25620359"/>
    </inertial>
  </link>

  <drake:collision_filter_group name="group_hl_uleg">
    <drake:member link="body"/>
    <drake:member link="hl_uleg"/>
    <drake:ignored_collision_filter_group name="group_hl_uleg"/>
  </drake:collision_filter_group>

  <joint name="hl_hy" type="revolute">
    <origin rpy="0 0 0" xyz="0.0 0.110945 0.0"/>
    <axis xyz="0 1 0"/>
    <parent link="hl_hip"/>
    <child link="hl_uleg"/>
    <!-- The velocity limits are for kinematic planning. The motors might move faster. -->
    <limit effort="45" lower="-0.898845" upper="2.295108" velocity="17"/>
  </joint>

  <transmission name="hl_hy_tran">
    <type>transmission_interface/SimpleTransmission</type>
    <joint name="hl_hy">
      <hardwareInterface>EffortJointInterface</hardwareInterface>
    </joint>
    <actuator name="hl_hy_motor">
      <hardwareInterface>EffortJointInterface</hardwareInterface>
    </actuator>
  </transmission>

  <!-- Rear Left Lower Leg -->
  <link name="hl_lleg">
    <visual>
      <geometry>
        <mesh filename="package://spot/meshes/base/visual/rear_left_lower_leg.obj"/>
      </geometry>
   </visual>
    <collision>
      <geometry>
        <mesh filename="package://spot/meshes/base/collision/left_lower_leg_collision.obj"/>
      </geometry>
    </collision>
    <collision>
      <origin xyz="0.0 0.0 -0.3365" rpy="0 0 0" />
      <geometry>
        <sphere radius="0.036"/>
      </geometry>
      <drake:proximity_properties>
        <drake:mu_static value="0.8"/>
        <drake:mu_dynamic value="0.7"/>
        <drake:hunt_crossley_dissipation value="2"/>
      </drake:proximity_properties>
    </collision>
    <inertial>
      <origin xyz="0.00597360 0.0 -0.17466427"/>
      <inertia ixx="0.00701356" ixy="0.0" ixz="0.00006600" iyy="0.00709946" iyz="0.0" izz="0.00014529"/>
      <mass value="0.330"/>
    </inertial>
  </link>
  <frame link="hl_lleg" name="rear_left_foot_center" xyz="0.0 0.0 -0.3365"/>

  <joint name="hl_kn" type="revolute">
    <origin rpy="0 0 0" xyz="0.025 0.000 -0.3205"/>
    <axis xyz="0 1 0"/>
    <parent link="hl_uleg"/>
    <child link="hl_lleg"/>
    <!-- The velocity limits are for kinematic planning and apply to the linkage
    input, which is modelled as a variable transmission outside of this URDF.
    Due to the high gear ratio, the limits at the motor seem very high.-->
    <limit effort="115" lower="-2.7929" upper="-0.2471" velocity="900"/>
  </joint>

  <transmission name="hl_kn_tran">
    <type>transmission_interface/SimpleTransmission</type>
    <joint name="hl_kn">
      <hardwareInterface>EffortJointInterface</hardwareInterface>
    </joint>
    <actuator name="hl_kn_motor">
      <hardwareInterface>EffortJointInterface</hardwareInterface>
    </actuator>
  </transmission>

  <!-- Rear Right Hip -->
  <link name="hr_hip">
    <visual>
      <geometry>
        <mesh filename="package://spot/meshes/base/visual/rear_right_hip.obj"/>
      </geometry>
   </visual>
    <inertial>
      <origin xyz="0.01586739 -0.00855842 0.00000903"/>
      <inertia ixx="0.00122166" ixy="-0.00017754" ixz="-0.00000043" iyy="0.00158957" iyz="0.00000049" izz="0.00172903"/>
      <mass value="1.13688339"/>
    </inertial>
  </link>

  <joint name="hr_hx" type="revolute">
    <origin rpy="0 0 0" xyz="-0.29785 -0.05500 0.00000"/>
    <axis xyz="1 0 0"/>
    <parent link="body"/>
    <child link="hr_hip"/>
    <!-- The velocity limits are for kinematic planning. The motors might move faster. -->
    <limit effort="45" lower="-0.785398" upper="0.785398" velocity="17"/>
  </joint>

  <transmission name="hr_hx_tran">
    <type>transmission_interface/SimpleTransmission</type>
    <joint name="hr_hx">
      <hardwareInterface>EffortJointInterface</hardwareInterface>
    </joint>
    <actuator name="hr_hx_motor">
      <hardwareInterface>EffortJointInterface</hardwareInterface>
    </actuator>
  </transmission>

  <!-- Rear Right Upper Leg -->
  <link name="hr_uleg">
    <visual>
      <geometry>
        <mesh filename="package://spot/meshes/base/visual/rear_right_upper_leg.obj"/>
      </geometry>
   </visual>
    <collision>
      <geometry>
        <mesh filename="package://spot/meshes/base/collision/right_upper_leg_collision.obj"/>
      </geometry>
    </collision>
    <inertial>
      <origin xyz="0.00214442 0.01110184 -0.07881204"/>
      <inertia ixx="0.02692501" ixy="0.00008782" ixz="0.00054873" iyy="0.02583907" iyz="-0.00207146" izz="0.00318737"/>
      <mass value="2.25620359"/>
    </inertial>
  </link>

  <drake:collision_filter_group name="group_hr_uleg">
    <drake:member link="body"/>
    <drake:member link="hr_uleg"/>
    <drake:ignored_collision_filter_group name="group_hr_uleg"/>
  </drake:collision_filter_group>

  <joint name="hr_hy" type="revolute">
    <origin rpy="0 0 0" xyz="0.0 -0.110945 0.0"/>
    <axis xyz="0 1 0"/>
    <parent link="hr_hip"/>
    <child link="hr_uleg"/>
    <!-- The velocity limits are for kinematic planning. The motors might move faster. -->
    <limit effort="45" lower="-0.898845" upper="2.295108" velocity="17"/>
  </joint>

  <transmission name="hr_hy_tran">
    <type>transmission_interface/SimpleTransmission</type>
    <joint name="hr_hy">
      <hardwareInterface>EffortJointInterface</hardwareInterface>
    </joint>
    <actuator name="hr_hy_motor">
      <hardwareInterface>EffortJointInterface</hardwareInterface>
    </actuator>
  </transmission>

  <!-- Rear Right Lower Leg -->
  <link name="hr_lleg">
    <visual>
      <geometry>
        <mesh filename="package://spot/meshes/base/visual/rear_right_lower_leg.obj"/>
      </geometry>
   </visual>
    <collision>
      <geometry>
        <mesh filename="package://spot/meshes/base/collision/right_lower_leg_collision.obj"/>
      </geometry>
    </collision>
    <collision>
      <origin xyz="0.0 0.0 -0.3365" rpy="0 0 0" />
      <geometry>
        <sphere radius="0.036"/>
      </geometry>
      <drake:proximity_properties>
        <drake:mu_static value="0.8"/>
        <drake:mu_dynamic value="0.7"/>
        <drake:hunt_crossley_dissipation value="2"/>
      </drake:proximity_properties>
    </collision>
    <inertial>
      <origin xyz="0.00597360 0.0 -0.17466427"/>
      <inertia ixx="0.00701356" ixy="0.0" ixz="0.00006600" iyy="0.00709946" iyz="0.0" izz="0.00014529"/>
      <mass value="0.330"/>
    </inertial>
  </link>
  <frame link="hr_lleg" name="rear_right_foot_center" xyz="0.0 0.0 -0.3365"/>

  <joint name="hr_kn" type="revolute">
    <origin rpy="0 0 0" xyz="0.025 0.000 -0.3205"/>
    <axis xyz="0 1 0"/>
    <parent link="hr_uleg"/>
    <child link="hr_lleg"/>
    <!-- The velocity limits are for kinematic planning and apply to the linkage
    input, which is modelled as a variable transmission outside of this URDF.
    Due to the high gear ratio, the limits at the motor seem very high.-->
    <limit effort="115" lower="-2.7929" upper="-0.2471" velocity="900"/>
  </joint>

  <transmission name="hr_kn_tran">
    <type>transmission_interface/SimpleTransmission</type>
    <joint name="hr_kn">
      <hardwareInterface>EffortJointInterface</hardwareInterface>
    </joint>
    <actuator name="hr_kn_motor">
      <hardwareInterface>EffortJointInterface</hardwareInterface>
    </actuator>
  </transmission>

  <!--Front left camera.-->
  <frame link="body" name="frontleft_camera_body" rpy="-2.61511 1.13222 3.13494" xyz="0.41567 0.03471 0.02471"/>
  <frame link="body" name="frontleft_color_sensor" rpy="-2.61399 1.13776 -3.13834" xyz="0.38433 0.03152 -0.04523"/>
  <frame link="body" name="frontleft_depth_sensor" rpy="-2.61511 1.13222 3.13494" xyz="0.41567 0.03471 0.02471"/>
  <!--Front right camera.-->
  <frame link="body" name="frontright_camera_body" rpy="2.59383 1.14532 -3.13694" xyz="0.41575 -0.03982 0.02482"/>
  <frame link="body" name="frontright_color_sensor" rpy="2.5944 1.13136 -3.12977" xyz="0.38585 -0.0405 -0.04699"/>
  <frame link="body" name="frontright_depth_sensor" rpy="2.59383 1.14532 -3.13694" xyz="0.41575 -0.03982 0.02482"/>
  <!--Left camera.-->
  <frame link="body" name="left_camera_body" rpy="-1.87443 -0.00134 0.00652" xyz="-0.16414 0.10891 0.03595"/>
  <frame link="body" name="left_color_sensor" rpy="-1.87864 -0.00398 0.01138" xyz="-0.08732 0.11259 0.03769"/>
  <frame link="body" name="left_depth_sensor" rpy="-1.87443 -0.00134 0.00652" xyz="-0.16414 0.10891 0.03595"/>
  <!--Right camera.-->
  <frame link="body" name="right_camera_body" rpy="1.83007 -0.0027 -0.00596" xyz="-0.16785 -0.10827 0.03641"/>
  <frame link="body" name="right_color_sensor" rpy="1.82817 0.00552 -0.00808" xyz="-0.09121 -0.11076 0.0333"/>
  <frame link="body" name="right_depth_sensor" rpy="1.83007 -0.0027 -0.00596" xyz="-0.16785 -0.10827 0.03641"/>
  <!--Back camera.-->
  <frame link="body" name="back_camera_body" rpy="-1.83718 -0.00212 1.56915" xyz="-0.41655 -0.03735 0.0093"/>
  <frame link="body" name="back_color_sensor" rpy="-1.84053 0.01849 1.571" xyz="-0.4196 0.04024 0.01096"/>
  <frame link="body" name="back_depth_sensor" rpy="-1.83718 -0.00212 1.56915" xyz="-0.41655 -0.03735 0.0093"/>
</robot>
